<sdf version='1.7'>
  <world name='default'>
    <light name='sun' type='directional'>
      <cast_shadows>1</cast_shadows>
      <pose>0 0 10 0 -0 0</pose>
      <diffuse>0.8 0.8 0.8 1</diffuse>
      <specular>0.2 0.2 0.2 1</specular>
      <attenuation>
        <range>1000</range>
        <constant>0.9</constant>
        <linear>0.01</linear>
        <quadratic>0.001</quadratic>
      </attenuation>
      <direction>-0.5 0.1 -0.9</direction>
      <spot>
        <inner_angle>0</inner_angle>
        <outer_angle>0</outer_angle>
        <falloff>0</falloff>
      </spot>
    </light>
    <model name='ground_plane'>
      <static>1</static>
      <link name='link'>
        <collision name='collision'>
          <geometry>
            <plane>
              <normal>0 0 1</normal>
              <size>100 100</size>
            </plane>
          </geometry>
          <surface>
            <contact>
              <collide_bitmask>65535</collide_bitmask>
              <ode/>
            </contact>
            <friction>
              <ode>
                <mu>100</mu>
                <mu2>50</mu2>
              </ode>
              <torsional>
                <ode/>
              </torsional>
            </friction>
            <bounce/>
          </surface>
          <max_contacts>10</max_contacts>
        </collision>
        <visual name='visual'>
          <cast_shadows>0</cast_shadows>
          <geometry>
            <plane>
              <normal>0 0 1</normal>
              <size>100 100</size>
            </plane>
          </geometry>
          <material>
            <script>
              <uri>file://media/materials/scripts/gazebo.material</uri>
              <name>Gazebo/Grey</name>
            </script>
          </material>
        </visual>
        <self_collide>0</self_collide>
        <enable_wind>0</enable_wind>
        <kinematic>0</kinematic>
      </link>
    </model>
    <gravity>0 0 -9.8</gravity>
    <magnetic_field>6e-06 2.3e-05 -4.2e-05</magnetic_field>
    <atmosphere type='adiabatic'/>
    <physics type='ode'>
      <max_step_size>0.001</max_step_size>
      <real_time_factor>1</real_time_factor>
      <real_time_update_rate>1000</real_time_update_rate>
    </physics>
    <scene>
      <ambient>0.4 0.4 0.4 1</ambient>
      <background>0.7 0.7 0.7 1</background>
      <shadows>1</shadows>
    </scene>
    <wind/>
    <spherical_coordinates>
      <surface_model>EARTH_WGS84</surface_model>
      <latitude_deg>0</latitude_deg>
      <longitude_deg>0</longitude_deg>
      <elevation>0</elevation>
      <heading_deg>0</heading_deg>
    </spherical_coordinates>
    <model name='mycarbot'>
      <link name='base_footprint'>
        <inertial>
          <pose>0 0 0.055 0 -0 0</pose>
          <mass>2</mass>
          <inertia>
            <ixx>0.00606667</ixx>
            <ixy>0</ixy>
            <ixz>0</ixz>
            <iyy>0.00606667</iyy>
            <iyz>0</iyz>
            <izz>0.01</izz>
          </inertia>
        </inertial>
        <collision name='base_footprint_fixed_joint_lump__base_link_collision'>
          <pose>0 0 0.055 0 -0 0</pose>
          <geometry>
            <cylinder>
              <length>0.08</length>
              <radius>0.1</radius>
            </cylinder>
          </geometry>
          <surface>
            <contact>
              <ode/>
            </contact>
            <friction>
              <ode/>
              <torsional>
                <ode/>
              </torsional>
            </friction>
            <bounce/>
          </surface>
          <max_contacts>10</max_contacts>
        </collision>
        <visual name='base_footprint_visual'>
          <pose>0 0 0 0 -0 0</pose>
          <geometry>
            <sphere>
              <radius>0.001</radius>
            </sphere>
          </geometry>
        </visual>
        <visual name='base_footprint_fixed_joint_lump__base_link_visual_1'>
          <pose>0 0 0.055 0 -0 0</pose>
          <geometry>
            <cylinder>
              <length>0.08</length>
              <radius>0.1</radius>
            </cylinder>
          </geometry>
          <material>
            <script>
              <name>Gazebo/Yellow</name>
              <uri>file://media/materials/scripts/gazebo.material</uri>
            </script>
          </material>
        </visual>
        <visual name='base_footprint_fixed_joint_lump__bracket_visual_2'>
          <pose>0 0 0.12 0 -0 0</pose>
          <geometry>
            <cylinder>
              <length>0.15</length>
              <radius>0.01</radius>
            </cylinder>
          </geometry>
        </visual>
        <visual name='base_footprint_fixed_joint_lump__lidar_visual_3'>
          <pose>0 0 0.22 0 -0 0</pose>
          <geometry>
            <cylinder>
              <length>0.05</length>
              <radius>0.03</radius>
            </cylinder>
          </geometry>
        </visual>
        <visual name='base_footprint_fixed_joint_lump__camera_visual_4'>
          <pose>0.08 0 0.12 0 -0 0</pose>
          <geometry>
            <box>
              <size>0.02 0.05 0.05</size>
            </box>
          </geometry>
        </visual>
        <self_collide>0</self_collide>
        <enable_wind>0</enable_wind>
        <kinematic>0</kinematic>
      </link>
      <joint name='back2link' type='revolute'>
        <pose relative_to='base_footprint'>-0.08 0 0.0075 0 -0 0</pose>
        <parent>base_footprint</parent>
        <child>back_wheel</child>
        <axis>
          <xyz>0 1 0</xyz>
          <limit>
            <lower>-1e+16</lower>
            <upper>1e+16</upper>
          </limit>
          <dynamics>
            <spring_reference>0</spring_reference>
            <spring_stiffness>0</spring_stiffness>
          </dynamics>
        </axis>
      </joint>
      <link name='back_wheel'>
        <pose relative_to='back2link'>0 0 0 0 -0 0</pose>
        <inertial>
          <pose>0 0 0 0 -0 0</pose>
          <mass>0.01</mass>
          <inertia>
            <ixx>2.25e-07</ixx>
            <ixy>0</ixy>
            <ixz>0</ixz>
            <iyy>2.25e-07</iyy>
            <iyz>0</iyz>
            <izz>2.25e-07</izz>
          </inertia>
        </inertial>
        <collision name='back_wheel_collision'>
          <pose>0 0 0 0 -0 0</pose>
          <geometry>
            <sphere>
              <radius>0.0075</radius>
            </sphere>
          </geometry>
          <max_contacts>10</max_contacts>
          <surface>
            <contact>
              <ode/>
            </contact>
            <bounce/>
            <friction>
              <torsional>
                <ode/>
              </torsional>
              <ode/>
            </friction>
          </surface>
        </collision>
        <visual name='back_wheel_visual'>
          <pose>0 0 0 0 -0 0</pose>
          <geometry>
            <sphere>
              <radius>0.0075</radius>
            </sphere>
          </geometry>
        </visual>
        <self_collide>0</self_collide>
        <enable_wind>0</enable_wind>
        <kinematic>0</kinematic>
      </link>
      <joint name='front2link' type='revolute'>
        <pose relative_to='base_footprint'>0.08 0 0.0075 0 -0 0</pose>
        <parent>base_footprint</parent>
        <child>front_wheel</child>
        <axis>
          <xyz>0 1 0</xyz>
          <limit>
            <lower>-1e+16</lower>
            <upper>1e+16</upper>
          </limit>
          <dynamics>
            <spring_reference>0</spring_reference>
            <spring_stiffness>0</spring_stiffness>
          </dynamics>
        </axis>
      </joint>
      <link name='front_wheel'>
        <pose relative_to='front2link'>0 0 0 0 -0 0</pose>
        <inertial>
          <pose>0 0 0 0 -0 0</pose>
          <mass>0.01</mass>
          <inertia>
            <ixx>2.25e-07</ixx>
            <ixy>0</ixy>
            <ixz>0</ixz>
            <iyy>2.25e-07</iyy>
            <iyz>0</iyz>
            <izz>2.25e-07</izz>
          </inertia>
        </inertial>
        <collision name='front_wheel_collision'>
          <pose>0 0 0 0 -0 0</pose>
          <geometry>
            <sphere>
              <radius>0.0075</radius>
            </sphere>
          </geometry>
          <max_contacts>10</max_contacts>
          <surface>
            <contact>
              <ode/>
            </contact>
            <bounce/>
            <friction>
              <torsional>
                <ode/>
              </torsional>
              <ode/>
            </friction>
          </surface>
        </collision>
        <visual name='front_wheel_visual'>
          <pose>0 0 0 0 -0 0</pose>
          <geometry>
            <sphere>
              <radius>0.0075</radius>
            </sphere>
          </geometry>
        </visual>
        <self_collide>0</self_collide>
        <enable_wind>0</enable_wind>
        <kinematic>0</kinematic>
      </link>
      <joint name='left2link' type='revolute'>
        <pose relative_to='base_footprint'>0 0.1 0.0325 0 -0 0</pose>
        <parent>base_footprint</parent>
        <child>left_wheel</child>
        <axis>
          <xyz>0 1 0</xyz>
          <limit>
            <lower>-1e+16</lower>
            <upper>1e+16</upper>
          </limit>
          <dynamics>
            <spring_reference>0</spring_reference>
            <spring_stiffness>0</spring_stiffness>
          </dynamics>
        </axis>
      </joint>
      <link name='left_wheel'>
        <pose relative_to='left2link'>0 0 0 0 -0 0</pose>
        <inertial>
          <pose>0 0 0 0 -0 0</pose>
          <mass>0.05</mass>
          <inertia>
            <ixx>1.41406e-05</ixx>
            <ixy>0</ixy>
            <ixz>0</ixz>
            <iyy>1.41406e-05</iyy>
            <iyz>0</iyz>
            <izz>2.64063e-05</izz>
          </inertia>
        </inertial>
        <collision name='left_wheel_collision'>
          <pose>0 0 0 1.5708 -0 0</pose>
          <geometry>
            <cylinder>
              <length>0.015</length>
              <radius>0.0325</radius>
            </cylinder>
          </geometry>
          <max_contacts>10</max_contacts>
          <surface>
            <contact>
              <ode/>
            </contact>
            <bounce/>
            <friction>
              <torsional>
                <ode/>
              </torsional>
              <ode/>
            </friction>
          </surface>
        </collision>
        <visual name='left_wheel_visual'>
          <pose>0 0 0 1.5708 -0 0</pose>
          <geometry>
            <cylinder>
              <length>0.015</length>
              <radius>0.0325</radius>
            </cylinder>
          </geometry>
        </visual>
        <self_collide>0</self_collide>
        <enable_wind>0</enable_wind>
        <kinematic>0</kinematic>
      </link>
      <joint name='right2link' type='revolute'>
        <pose relative_to='base_footprint'>0 -0.1 0.0325 0 -0 0</pose>
        <parent>base_footprint</parent>
        <child>right_wheel</child>
        <axis>
          <xyz>0 1 0</xyz>
          <limit>
            <lower>-1e+16</lower>
            <upper>1e+16</upper>
          </limit>
          <dynamics>
            <spring_reference>0</spring_reference>
            <spring_stiffness>0</spring_stiffness>
          </dynamics>
        </axis>
      </joint>
      <link name='right_wheel'>
        <pose relative_to='right2link'>0 0 0 0 -0 0</pose>
        <inertial>
          <pose>0 0 0 0 -0 0</pose>
          <mass>0.05</mass>
          <inertia>
            <ixx>1.41406e-05</ixx>
            <ixy>0</ixy>
            <ixz>0</ixz>
            <iyy>1.41406e-05</iyy>
            <iyz>0</iyz>
            <izz>2.64063e-05</izz>
          </inertia>
        </inertial>
        <collision name='right_wheel_collision'>
          <pose>0 0 0 1.5708 -0 0</pose>
          <geometry>
            <cylinder>
              <length>0.015</length>
              <radius>0.0325</radius>
            </cylinder>
          </geometry>
          <max_contacts>10</max_contacts>
          <surface>
            <contact>
              <ode/>
            </contact>
            <bounce/>
            <friction>
              <torsional>
                <ode/>
              </torsional>
              <ode/>
            </friction>
          </surface>
        </collision>
        <visual name='right_wheel_visual'>
          <pose>0 0 0 1.5708 -0 0</pose>
          <geometry>
            <cylinder>
              <length>0.015</length>
              <radius>0.0325</radius>
            </cylinder>
          </geometry>
        </visual>
        <self_collide>0</self_collide>
        <enable_wind>0</enable_wind>
        <kinematic>0</kinematic>
      </link>
      <static>0</static>
      <pose>0 0 0 0 -0 0</pose>
    </model>
    <state world_name='default'>
      <sim_time>423 85000000</sim_time>
      <real_time>427 507847902</real_time>
      <wall_time>1720675153 602592075</wall_time>
      <iterations>423085</iterations>
      <model name='ground_plane'>
        <pose>0 0 0 0 -0 0</pose>
        <scale>1 1 1</scale>
        <link name='link'>
          <pose>0 0 0 0 -0 0</pose>
          <velocity>0 0 0 0 -0 0</velocity>
          <acceleration>0 0 0 0 -0 0</acceleration>
          <wrench>0 0 0 0 -0 0</wrench>
        </link>
      </model>
      <model name='mycarbot'>
        <pose>0.036661 -0.119557 -7e-06 -6.3e-05 1e-06 -0.004449</pose>
        <scale>1 1 1</scale>
        <link name='back_wheel'>
          <pose>-0.043338 -0.119205 0.007495 -0.002675 -0.912817 -0.002332</pose>
          <velocity>-0.000957 -0.002993 -0.005994 0.29203 -0.123619 0.000558</velocity>
          <acceleration>-0.043397 -3.81261 -7.34971 -1.69525 -1.40227 -2.9625</acceleration>
          <wrench>-0.000434 -0.038126 -0.073497 0 -0 0</wrench>
        </link>
        <link name='base_footprint'>
          <pose>0.036661 -0.119557 -7e-06 -6.3e-05 1e-06 -0.004449</pose>
          <velocity>-0.000962 -0.004907 -0.005486 -0.100505 0.000554 0.00032</velocity>
          <acceleration>0.006177 1.33232 -4.12359 2.64449 0.623917 0.165647</acceleration>
          <wrench>0.012354 2.66464 -8.24719 0 -0 0</wrench>
        </link>
        <link name='front_wheel'>
          <pose>0.11666 -0.119917 0.007495 -0.010688 -1.41535 0.00611</pose>
          <velocity>-0.000952 -0.002929 -0.006031 0.296764 -0.126616 0.000597</velocity>
          <acceleration>-0.016138 -3.76655 -7.37528 -0.942124 -1.37098 -2.91916</acceleration>
          <wrench>-0.000161 -0.037665 -0.073753 0 -0 0</wrench>
        </link>
        <link name='left_wheel'>
          <pose>0.037106 -0.019557 0.032487 -0.000454 1.21097 -0.004848</pose>
          <velocity>-0.000981 -0.001221 -0.01578 -0.076523 -0.029683 -0.006027</velocity>
          <acceleration>-0.023033 -1.9612 -18.2193 -0.302686 0.396464 0.622822</acceleration>
          <wrench>-0.001152 -0.09806 -0.910967 0 -0 0</wrench>
        </link>
        <link name='right_wheel'>
          <pose>0.036216 -0.219549 0.032501 0.000456 1.09076 -0.00412</pose>
          <velocity>-0.000902 -6.2e-05 0.004695 0.001592 -0.026524 -0.028287</velocity>
          <acceleration>0.024721 0.459549 10.5744 -2.60488 -1.32334 1.11187</acceleration>
          <wrench>0.001236 0.022977 0.52872 0 -0 0</wrench>
        </link>
      </model>
      <light name='sun'>
        <pose>0 0 10 0 -0 0</pose>
      </light>
    </state>
    <gui fullscreen='0'>
      <camera name='user_camera'>
        <pose>6.43469 0.82863 2.96549 0 0.399643 3.0562</pose>
        <view_controller>orbit</view_controller>
        <projection_type>perspective</projection_type>
      </camera>
    </gui>
  </world>
</sdf>
